[2024-07-03T23:10:57.926+0000] {local_task_job_runner.py:120} INFO - ::group::Pre task execution logs
[2024-07-03T23:10:58.074+0000] {taskinstance.py:2076} INFO - Dependencies all met for dep_context=non-requeueable deps ti=<TaskInstance: Proyecto_Final_USD_ETL.download_data manual__2024-07-03T23:10:55.740002+00:00 [queued]>
[2024-07-03T23:10:58.079+0000] {taskinstance.py:2076} INFO - Dependencies all met for dep_context=requeueable deps ti=<TaskInstance: Proyecto_Final_USD_ETL.download_data manual__2024-07-03T23:10:55.740002+00:00 [queued]>
[2024-07-03T23:10:58.080+0000] {taskinstance.py:2306} INFO - Starting attempt 1 of 6
[2024-07-03T23:10:58.090+0000] {taskinstance.py:2330} INFO - Executing <Task(PythonOperator): download_data> on 2024-07-03 23:10:55.740002+00:00
[2024-07-03T23:10:58.095+0000] {warnings.py:112} WARNING - /home/***/.local/lib/python3.12/site-packages/***/task/task_runner/standard_task_runner.py:61: DeprecationWarning: This process (pid=360) is multi-threaded, use of fork() may lead to deadlocks in the child.
  pid = os.fork()

[2024-07-03T23:10:58.096+0000] {standard_task_runner.py:63} INFO - Started process 362 to run task
[2024-07-03T23:10:58.096+0000] {standard_task_runner.py:90} INFO - Running: ['***', 'tasks', 'run', 'Proyecto_Final_USD_ETL', 'download_data', 'manual__2024-07-03T23:10:55.740002+00:00', '--job-id', '82', '--raw', '--subdir', 'DAGS_FOLDER/ETL_USD.py', '--cfg-path', '/tmp/tmpt44qnz5c']
[2024-07-03T23:10:58.097+0000] {standard_task_runner.py:91} INFO - Job 82: Subtask download_data
[2024-07-03T23:10:58.127+0000] {task_command.py:426} INFO - Running <TaskInstance: Proyecto_Final_USD_ETL.download_data manual__2024-07-03T23:10:55.740002+00:00 [running]> on host 5a0cf2cc04d9
[2024-07-03T23:10:58.182+0000] {taskinstance.py:2648} INFO - Exporting env vars: AIRFLOW_CTX_DAG_OWNER='gabor' AIRFLOW_CTX_DAG_ID='Proyecto_Final_USD_ETL' AIRFLOW_CTX_TASK_ID='download_data' AIRFLOW_CTX_EXECUTION_DATE='2024-07-03T23:10:55.740002+00:00' AIRFLOW_CTX_TRY_NUMBER='1' AIRFLOW_CTX_DAG_RUN_ID='manual__2024-07-03T23:10:55.740002+00:00'
[2024-07-03T23:10:58.183+0000] {taskinstance.py:430} INFO - ::endgroup::
[2024-07-03T23:10:59.479+0000] {logging_mixin.py:188} INFO - Connected to Redshift successfully!
[2024-07-03T23:10:59.669+0000] {ETL_USD.py:73} INFO - <class 'pandas.core.frame.DataFrame'>
RangeIndex: 7 entries, 0 to 6
Data columns (total 6 columns):
 #   Column              Non-Null Count  Dtype  
---  ------              --------------  -----  
 0   moneda              7 non-null      object 
 1   casa                7 non-null      object 
 2   nombre              7 non-null      object 
 3   compra              7 non-null      float64
 4   venta               7 non-null      float64
 5   fechaActualizacion  7 non-null      object 
dtypes: float64(2), object(4)
memory usage: 468.0+ bytes

[2024-07-03T23:10:59.670+0000] {ETL_USD.py:74} INFO - Data created
[2024-07-03T23:10:59.672+0000] {logging_mixin.py:188} INFO - Failed to upload data
[2024-07-03T23:10:59.672+0000] {taskinstance.py:441} INFO - ::group::Post task execution logs
[2024-07-03T23:10:59.673+0000] {taskinstance.py:2905} ERROR - Task failed with exception
Traceback (most recent call last):
  File "/home/airflow/.local/lib/python3.12/site-packages/airflow/models/taskinstance.py", line 465, in _execute_task
    result = _execute_callable(context=context, **execute_callable_kwargs)
             ^^^^^^^^^^^^^^^^^^^^^^^^^^^^^^^^^^^^^^^^^^^^^^^^^^^^^^^^^^^^^
  File "/home/airflow/.local/lib/python3.12/site-packages/airflow/models/taskinstance.py", line 432, in _execute_callable
    return execute_callable(context=context, **execute_callable_kwargs)
           ^^^^^^^^^^^^^^^^^^^^^^^^^^^^^^^^^^^^^^^^^^^^^^^^^^^^^^^^^^^^
  File "/home/airflow/.local/lib/python3.12/site-packages/airflow/models/baseoperator.py", line 401, in wrapper
    return func(self, *args, **kwargs)
           ^^^^^^^^^^^^^^^^^^^^^^^^^^^
  File "/home/airflow/.local/lib/python3.12/site-packages/airflow/operators/python.py", line 235, in execute
    return_value = self.execute_callable()
                   ^^^^^^^^^^^^^^^^^^^^^^^
  File "/home/airflow/.local/lib/python3.12/site-packages/airflow/operators/python.py", line 252, in execute_callable
    return self.python_callable(*self.op_args, **self.op_kwargs)
           ^^^^^^^^^^^^^^^^^^^^^^^^^^^^^^^^^^^^^^^^^^^^^^^^^^^^^
  File "/opt/airflow/dags/ETL_USD.py", line 126, in process_data
    upload_data(conn=conn_data, data=df, table="stage_api_dolarucos")
  File "/opt/airflow/dags/ETL_USD.py", line 89, in upload_data
    redshift_ids_query = f"SELECT id FROM {self.schema}.{table}"
                                           ^^^^
NameError: name 'self' is not defined
[2024-07-03T23:10:59.682+0000] {taskinstance.py:1206} INFO - Marking task as UP_FOR_RETRY. dag_id=Proyecto_Final_USD_ETL, task_id=download_data, run_id=manual__2024-07-03T23:10:55.740002+00:00, execution_date=20240703T231055, start_date=20240703T231058, end_date=20240703T231059
[2024-07-03T23:10:59.695+0000] {standard_task_runner.py:110} ERROR - Failed to execute job 82 for task download_data (name 'self' is not defined; 362)
[2024-07-03T23:10:59.713+0000] {local_task_job_runner.py:240} INFO - Task exited with return code 1
[2024-07-03T23:10:59.730+0000] {taskinstance.py:3503} INFO - 0 downstream tasks scheduled from follow-on schedule check
[2024-07-03T23:10:59.734+0000] {local_task_job_runner.py:222} INFO - ::endgroup::
