[2024-07-03T23:24:31.196+0000] {local_task_job_runner.py:120} INFO - ::group::Pre task execution logs
[2024-07-03T23:24:31.364+0000] {taskinstance.py:2076} INFO - Dependencies all met for dep_context=non-requeueable deps ti=<TaskInstance: Proyecto_Final_USD_ETL.download_data manual__2024-07-03T23:24:29.181165+00:00 [queued]>
[2024-07-03T23:24:31.371+0000] {taskinstance.py:2076} INFO - Dependencies all met for dep_context=requeueable deps ti=<TaskInstance: Proyecto_Final_USD_ETL.download_data manual__2024-07-03T23:24:29.181165+00:00 [queued]>
[2024-07-03T23:24:31.372+0000] {taskinstance.py:2306} INFO - Starting attempt 1 of 6
[2024-07-03T23:24:31.383+0000] {taskinstance.py:2330} INFO - Executing <Task(PythonOperator): download_data> on 2024-07-03 23:24:29.181165+00:00
[2024-07-03T23:24:31.389+0000] {warnings.py:112} WARNING - /home/***/.local/lib/python3.12/site-packages/***/task/task_runner/standard_task_runner.py:61: DeprecationWarning: This process (pid=572) is multi-threaded, use of fork() may lead to deadlocks in the child.
  pid = os.fork()

[2024-07-03T23:24:31.390+0000] {standard_task_runner.py:63} INFO - Started process 574 to run task
[2024-07-03T23:24:31.390+0000] {standard_task_runner.py:90} INFO - Running: ['***', 'tasks', 'run', 'Proyecto_Final_USD_ETL', 'download_data', 'manual__2024-07-03T23:24:29.181165+00:00', '--job-id', '93', '--raw', '--subdir', 'DAGS_FOLDER/ETL_USD.py', '--cfg-path', '/tmp/tmpyrnn33j6']
[2024-07-03T23:24:31.391+0000] {standard_task_runner.py:91} INFO - Job 93: Subtask download_data
[2024-07-03T23:24:31.424+0000] {task_command.py:426} INFO - Running <TaskInstance: Proyecto_Final_USD_ETL.download_data manual__2024-07-03T23:24:29.181165+00:00 [running]> on host 5a0cf2cc04d9
[2024-07-03T23:24:31.484+0000] {taskinstance.py:2648} INFO - Exporting env vars: AIRFLOW_CTX_DAG_OWNER='gabor' AIRFLOW_CTX_DAG_ID='Proyecto_Final_USD_ETL' AIRFLOW_CTX_TASK_ID='download_data' AIRFLOW_CTX_EXECUTION_DATE='2024-07-03T23:24:29.181165+00:00' AIRFLOW_CTX_TRY_NUMBER='1' AIRFLOW_CTX_DAG_RUN_ID='manual__2024-07-03T23:24:29.181165+00:00'
[2024-07-03T23:24:31.485+0000] {taskinstance.py:430} INFO - ::endgroup::
[2024-07-03T23:24:32.712+0000] {logging_mixin.py:188} INFO - Connected to Redshift successfully!
[2024-07-03T23:24:32.859+0000] {ETL_USD.py:73} INFO - <class 'pandas.core.frame.DataFrame'>
RangeIndex: 7 entries, 0 to 6
Data columns (total 6 columns):
 #   Column              Non-Null Count  Dtype  
---  ------              --------------  -----  
 0   moneda              7 non-null      object 
 1   casa                7 non-null      object 
 2   nombre              7 non-null      object 
 3   compra              7 non-null      float64
 4   venta               7 non-null      float64
 5   fechaActualizacion  7 non-null      object 
dtypes: float64(2), object(4)
memory usage: 468.0+ bytes

[2024-07-03T23:24:32.860+0000] {ETL_USD.py:74} INFO - Data created
[2024-07-03T23:24:32.866+0000] {warnings.py:112} WARNING - /opt/***/dags/ETL_USD.py:90: UserWarning: pandas only supports SQLAlchemy connectable (engine/connection) or database string URI or sqlite3 DBAPI2 connection. Other DBAPI2 objects are not tested. Please consider using SQLAlchemy.
  redshift_ids = pd.read_sql(redshift_ids_query, con=conn)

[2024-07-03T23:24:44.161+0000] {logging_mixin.py:188} INFO - Data from the DataFrame has been uploaded to the table in Redshift.
[2024-07-03T23:24:44.162+0000] {taskinstance.py:441} INFO - ::group::Post task execution logs
[2024-07-03T23:24:44.162+0000] {taskinstance.py:2905} ERROR - Task failed with exception
Traceback (most recent call last):
  File "/home/airflow/.local/lib/python3.12/site-packages/airflow/models/taskinstance.py", line 465, in _execute_task
    result = _execute_callable(context=context, **execute_callable_kwargs)
             ^^^^^^^^^^^^^^^^^^^^^^^^^^^^^^^^^^^^^^^^^^^^^^^^^^^^^^^^^^^^^
  File "/home/airflow/.local/lib/python3.12/site-packages/airflow/models/taskinstance.py", line 432, in _execute_callable
    return execute_callable(context=context, **execute_callable_kwargs)
           ^^^^^^^^^^^^^^^^^^^^^^^^^^^^^^^^^^^^^^^^^^^^^^^^^^^^^^^^^^^^
  File "/home/airflow/.local/lib/python3.12/site-packages/airflow/models/baseoperator.py", line 401, in wrapper
    return func(self, *args, **kwargs)
           ^^^^^^^^^^^^^^^^^^^^^^^^^^^
  File "/home/airflow/.local/lib/python3.12/site-packages/airflow/operators/python.py", line 235, in execute
    return_value = self.execute_callable()
                   ^^^^^^^^^^^^^^^^^^^^^^^
  File "/home/airflow/.local/lib/python3.12/site-packages/airflow/operators/python.py", line 252, in execute_callable
    return self.python_callable(*self.op_args, **self.op_kwargs)
           ^^^^^^^^^^^^^^^^^^^^^^^^^^^^^^^^^^^^^^^^^^^^^^^^^^^^^
  File "/opt/airflow/dags/ETL_USD.py", line 127, in process_data
    conn.close()
    ^^^^
NameError: name 'conn' is not defined
[2024-07-03T23:24:44.170+0000] {taskinstance.py:1206} INFO - Marking task as UP_FOR_RETRY. dag_id=Proyecto_Final_USD_ETL, task_id=download_data, run_id=manual__2024-07-03T23:24:29.181165+00:00, execution_date=20240703T232429, start_date=20240703T232431, end_date=20240703T232444
[2024-07-03T23:24:44.183+0000] {standard_task_runner.py:110} ERROR - Failed to execute job 93 for task download_data (name 'conn' is not defined; 574)
[2024-07-03T23:24:44.220+0000] {local_task_job_runner.py:240} INFO - Task exited with return code 1
[2024-07-03T23:24:44.233+0000] {taskinstance.py:3503} INFO - 0 downstream tasks scheduled from follow-on schedule check
[2024-07-03T23:24:44.237+0000] {local_task_job_runner.py:222} INFO - ::endgroup::
