[2024-07-03T23:20:23.744+0000] {local_task_job_runner.py:120} INFO - ::group::Pre task execution logs
[2024-07-03T23:20:23.923+0000] {taskinstance.py:2076} INFO - Dependencies all met for dep_context=non-requeueable deps ti=<TaskInstance: Proyecto_Final_USD_ETL.download_data manual__2024-07-03T23:15:18.720387+00:00 [queued]>
[2024-07-03T23:20:23.928+0000] {taskinstance.py:2076} INFO - Dependencies all met for dep_context=requeueable deps ti=<TaskInstance: Proyecto_Final_USD_ETL.download_data manual__2024-07-03T23:15:18.720387+00:00 [queued]>
[2024-07-03T23:20:23.929+0000] {taskinstance.py:2306} INFO - Starting attempt 2 of 6
[2024-07-03T23:20:23.941+0000] {taskinstance.py:2330} INFO - Executing <Task(PythonOperator): download_data> on 2024-07-03 23:15:18.720387+00:00
[2024-07-03T23:20:23.946+0000] {warnings.py:112} WARNING - /home/***/.local/lib/python3.12/site-packages/***/task/task_runner/standard_task_runner.py:61: DeprecationWarning: This process (pid=495) is multi-threaded, use of fork() may lead to deadlocks in the child.
  pid = os.fork()

[2024-07-03T23:20:23.948+0000] {standard_task_runner.py:63} INFO - Started process 497 to run task
[2024-07-03T23:20:23.948+0000] {standard_task_runner.py:90} INFO - Running: ['***', 'tasks', 'run', 'Proyecto_Final_USD_ETL', 'download_data', 'manual__2024-07-03T23:15:18.720387+00:00', '--job-id', '87', '--raw', '--subdir', 'DAGS_FOLDER/ETL_USD.py', '--cfg-path', '/tmp/tmp5q__m0sk']
[2024-07-03T23:20:23.950+0000] {standard_task_runner.py:91} INFO - Job 87: Subtask download_data
[2024-07-03T23:20:23.986+0000] {task_command.py:426} INFO - Running <TaskInstance: Proyecto_Final_USD_ETL.download_data manual__2024-07-03T23:15:18.720387+00:00 [running]> on host 5a0cf2cc04d9
[2024-07-03T23:20:24.044+0000] {taskinstance.py:2648} INFO - Exporting env vars: AIRFLOW_CTX_DAG_OWNER='gabor' AIRFLOW_CTX_DAG_ID='Proyecto_Final_USD_ETL' AIRFLOW_CTX_TASK_ID='download_data' AIRFLOW_CTX_EXECUTION_DATE='2024-07-03T23:15:18.720387+00:00' AIRFLOW_CTX_TRY_NUMBER='2' AIRFLOW_CTX_DAG_RUN_ID='manual__2024-07-03T23:15:18.720387+00:00'
[2024-07-03T23:20:24.045+0000] {taskinstance.py:430} INFO - ::endgroup::
[2024-07-03T23:20:25.292+0000] {logging_mixin.py:188} INFO - Connected to Redshift successfully!
[2024-07-03T23:20:25.482+0000] {ETL_USD.py:73} INFO - <class 'pandas.core.frame.DataFrame'>
RangeIndex: 7 entries, 0 to 6
Data columns (total 6 columns):
 #   Column              Non-Null Count  Dtype  
---  ------              --------------  -----  
 0   moneda              7 non-null      object 
 1   casa                7 non-null      object 
 2   nombre              7 non-null      object 
 3   compra              7 non-null      float64
 4   venta               7 non-null      float64
 5   fechaActualizacion  7 non-null      object 
dtypes: float64(2), object(4)
memory usage: 468.0+ bytes

[2024-07-03T23:20:25.483+0000] {ETL_USD.py:74} INFO - Data created
[2024-07-03T23:20:25.489+0000] {warnings.py:112} WARNING - /opt/***/dags/ETL_USD.py:90: UserWarning: pandas only supports SQLAlchemy connectable (engine/connection) or database string URI or sqlite3 DBAPI2 connection. Other DBAPI2 objects are not tested. Please consider using SQLAlchemy.
  redshift_ids = pd.read_sql(redshift_ids_query, con=conn)

[2024-07-03T23:20:26.429+0000] {logging_mixin.py:188} INFO - Failed to upload data
[2024-07-03T23:20:26.430+0000] {taskinstance.py:441} INFO - ::group::Post task execution logs
[2024-07-03T23:20:26.430+0000] {taskinstance.py:2905} ERROR - Task failed with exception
Traceback (most recent call last):
  File "/home/airflow/.local/lib/python3.12/site-packages/airflow/models/taskinstance.py", line 465, in _execute_task
    result = _execute_callable(context=context, **execute_callable_kwargs)
             ^^^^^^^^^^^^^^^^^^^^^^^^^^^^^^^^^^^^^^^^^^^^^^^^^^^^^^^^^^^^^
  File "/home/airflow/.local/lib/python3.12/site-packages/airflow/models/taskinstance.py", line 432, in _execute_callable
    return execute_callable(context=context, **execute_callable_kwargs)
           ^^^^^^^^^^^^^^^^^^^^^^^^^^^^^^^^^^^^^^^^^^^^^^^^^^^^^^^^^^^^
  File "/home/airflow/.local/lib/python3.12/site-packages/airflow/models/baseoperator.py", line 401, in wrapper
    return func(self, *args, **kwargs)
           ^^^^^^^^^^^^^^^^^^^^^^^^^^^
  File "/home/airflow/.local/lib/python3.12/site-packages/airflow/operators/python.py", line 235, in execute
    return_value = self.execute_callable()
                   ^^^^^^^^^^^^^^^^^^^^^^^
  File "/home/airflow/.local/lib/python3.12/site-packages/airflow/operators/python.py", line 252, in execute_callable
    return self.python_callable(*self.op_args, **self.op_kwargs)
           ^^^^^^^^^^^^^^^^^^^^^^^^^^^^^^^^^^^^^^^^^^^^^^^^^^^^^
  File "/opt/airflow/dags/ETL_USD.py", line 126, in process_data
    upload_data(conn=conn_data, data=df, table="stage_api_dolarucos")
  File "/opt/airflow/dags/ETL_USD.py", line 113, in upload_data
    execute_values(cur, insert_sql, values)
    ^^^^^^^^^^^^^^
NameError: name 'execute_values' is not defined
[2024-07-03T23:20:26.440+0000] {taskinstance.py:1206} INFO - Marking task as UP_FOR_RETRY. dag_id=Proyecto_Final_USD_ETL, task_id=download_data, run_id=manual__2024-07-03T23:15:18.720387+00:00, execution_date=20240703T231518, start_date=20240703T232023, end_date=20240703T232026
[2024-07-03T23:20:26.451+0000] {standard_task_runner.py:110} ERROR - Failed to execute job 87 for task download_data (name 'execute_values' is not defined; 497)
[2024-07-03T23:20:26.489+0000] {local_task_job_runner.py:240} INFO - Task exited with return code 1
[2024-07-03T23:20:26.504+0000] {taskinstance.py:3503} INFO - 0 downstream tasks scheduled from follow-on schedule check
[2024-07-03T23:20:26.508+0000] {local_task_job_runner.py:222} INFO - ::endgroup::
